(dp1
S'output'
p2
S'<type \'exceptions.RuntimeError\'> Failure to connect, tried 5 times:\nTraceback (most recent call last):\n  File "/home/mdipierro/make_web2py/web2py/gluon/dal.py", line 7845, in __init__\n  File "/home/mdipierro/make_web2py/web2py/gluon/dal.py", line 688, in __call__\n  File "/home/mdipierro/make_web2py/web2py/gluon/dal.py", line 2728, in __init__\n  File "/home/mdipierro/make_web2py/web2py/gluon/dal.py", line 648, in reconnect\n  File "/home/mdipierro/make_web2py/web2py/gluon/dal.py", line 2726, in connector\n  File "/home/mdipierro/make_web2py/web2py/gluon/contrib/pymysql/__init__.py", line 93, in Connect\n  File "/home/mdipierro/make_web2py/web2py/gluon/contrib/pymysql/connections.py", line 575, in __init__\n  File "/home/mdipierro/make_web2py/web2py/gluon/contrib/pymysql/connections.py", line 743, in _connect\nOperationalError: (2003, "Can\'t connect to MySQL server on \'localhost\' (10061)")\n'
p3
sS'layer'
p4
S'C:\\Users\\Leandro\\Documents\\CJR\\DIPRO\\PROJETOS\\G\xeanios\\genios\\ProjetoGenios\\web2py\\applications\\Genios\\models\\db.py'
p5
sS'code'
p6
S'db = DAL(\'mysql://root:Ca_784595@localhost/mydb\',migrate=False,lazy_tables=True) # Conecta com o banco\n\n\ndb.define_table(\'pai\',Field(\'nome\'),Field(\'ativo\',\'boolean\'),Field(\'nome\',\'text\'),format = \'%(nome)s\')\ndb.define_table(\'filho\',\n                Field(\'fk_pai\', \'reference pai\'),\n                Field(\'foto\',\'upload\', uploadfield=\'foto_arquivo\'),\n                Field(\'foto_arquivo\',\'blob\'),Field(\'ativo\',\'boolean\'),\n                Field(\'nome\'),\n                Field(\'colegio\'),\n                Field(\'ano\',\'integer\')\n                ,format = \'%(nome)s\')\ndb.define_table(\'pai_x_filho\',Field(\'fk_pai\',\'reference tb_usuario\'),Field(\'fk_filho\',\'reference filho\') )\n\ndb.define_table(\'tb_perfil\',\n                Field(\'id_perfil\',\'id\'),\n                Field(\'nome\'),\n                Field(\'ativo\',\'boolean\'),\n                redefine=True,\n                format = \'%(nome)s\')\n\n\ndb.define_table("tb_usuario",\n                Field(\'id_usuario\',\'id\'),\n                Field(\'nome\'),\n                Field(\'fk_id_perfil\',\'reference tb_perfil\'),\n                Field(\'email\'),\n                Field(\'senha\',\'password\'),\n                Field(\'numero_filhos\',\'integer\'),\n                Field(\'ano_escolar\',\'integer\'),\n                Field(\'ativo\',\'boolean\'),\n                redefine=True,\n                format = \'%(nome)s\')\n'
p7
sS'snapshot'
p8
(dp9
sS'traceback'
p10
S'Traceback (most recent call last):\n  File "/home/mdipierro/make_web2py/web2py/gluon/restricted.py", line 220, in restricted\n  File "C:\\Users\\Leandro\\Documents\\CJR\\DIPRO\\PROJETOS\\G\xeanios\\genios\\ProjetoGenios\\web2py\\applications\\Genios\\models\\db.py", line 1, in <module>\n    db = DAL(\'mysql://root:Ca_784595@localhost/mydb\',migrate=False,lazy_tables=True) # Conecta com o banco\n  File "/home/mdipierro/make_web2py/web2py/gluon/dal.py", line 7867, in __init__\nRuntimeError: Failure to connect, tried 5 times:\nTraceback (most recent call last):\n  File "/home/mdipierro/make_web2py/web2py/gluon/dal.py", line 7845, in __init__\n  File "/home/mdipierro/make_web2py/web2py/gluon/dal.py", line 688, in __call__\n  File "/home/mdipierro/make_web2py/web2py/gluon/dal.py", line 2728, in __init__\n  File "/home/mdipierro/make_web2py/web2py/gluon/dal.py", line 648, in reconnect\n  File "/home/mdipierro/make_web2py/web2py/gluon/dal.py", line 2726, in connector\n  File "/home/mdipierro/make_web2py/web2py/gluon/contrib/pymysql/__init__.py", line 93, in Connect\n  File "/home/mdipierro/make_web2py/web2py/gluon/contrib/pymysql/connections.py", line 575, in __init__\n  File "/home/mdipierro/make_web2py/web2py/gluon/contrib/pymysql/connections.py", line 743, in _connect\nOperationalError: (2003, "Can\'t connect to MySQL server on \'localhost\' (10061)")\n\n'
p11
s.